Workbook

Sheet Fire Accidents
A1: Year | B1: Serial no. in report (year) | C1: Date | D1: Time | E1: Mine | F1: Owner / company | G1: District | H1: State | I1: Persons killed | J1: Victims (name | designation | sex | age) | K1: Height / distance (m) | L1: Size / distance as printed | M1: Material / equipment involved | N1: Working area | O1: Activity at time (keywords) | P1: Fire or heating known beforehand (narrative) | Q1: Regulations cited (numbers) | R1: Regulations cited (rules) | S1: Narrative (what happened) | T1: Preventive analysis ("Had...") | U1: PDF page | V1: Cause group (fire classification) | W1: Cause category in report (code) | X1: Place (classification)
A2: 2016 | B2: 58 | C2: 2016-02-22 | D2: 16:45 | E2: SALANPUR | F2: BHARAT COKING COAL LTD. | G2: Dhanbad | H2: Jharkhand | I2: 1 | J2: Chandradeo Nonia | Dozer Operator | Male | 47 | M2: dozer | N2: opencast (berm / haul road) | O2: reversing dozer | Q2: 42(3); 190; 50(a); 36(1)(b) | R2: CMR 1957 | S2: While a dozer, not in safe working order was being marched, in reverse direction, the right side track chain of dozer run over berm resulted in topling of dozer. Dozer caught fire causing burn injuries to the operator which proved fatal almost instantly. | T2: Had, i) the working place was carefully examined by the assistant manager, after blasting prior to deployment of dozer, thereby not endangering the life and safety of dozer operator as required under regulation 42(3), read with regulation 190 of the Coal mines regulations, 1957. ii) the dozer was properly maintained, in safe working order to avoid occurrence of fire in the dozer, thereby not endangering the life and safety of dozer operator as required under the regulation 50(a), read with regulation 190 of the coal mines regulations, 1957. iii) the dozer was equipped with automatic fire detection and suppression system or semi-automatic type firefighting arrangement system as required under regulation 190 of the coal mines regulations, 1957 read with circular no. 10/2004. iv) the opencast sections were kept under supervision of assistant manager or under manager and of an experienced overman in the afternoon shift. As required under regulation 36(1)(b) of the coal mines regulations, 1957, this accident could have been averted. | U2: 77 | V2: Vehicle / machinery fire | W2: 0779 Other Accidents due to Dust/Gas/Fire | X2: Opencast
A3: 2016 | B3: 56 | C3: 2016-03-12 | D3: 17:45 | E3: CHHATARPUR MINE NO.I | F3: WESTERN COALFIELDS LTD. | G3: Betul | H3: Madhya Pradesh | I3: 1 | J3: Prakash Bihare | Blasting crewman | Male | 40 | K3: 2.5 | L3: within 2.5m of opposite gallery | M3: inflammable gas (methane) | N3: development face (underground) | O3: blasting / firing shots; guard posted | Q3: 175(2); 168(15); 173(a); 175; 113(3)(b); 143; 130(1); 146(1); 136 | R3: CMR 1957 | S3: While development face lying within 2.5m of an opposite gallery, was blasted in an underground coal mine, it ignited the inflammable gas accumulated therein the opposite gallery, inflicting serious burn injuries to a blasting crewman posted as guard, who died in the hospital after about forty two hours during treatment. | T3: Had, i) the test for presence of inflammable gas in the joining gallery lying within 2.5m of the face of firing been made before charging and firing the shots as required under the provisions of Regulation 175(2) of the coal mines regulation 1957; ii) the tests for inflammable gas been made in the area lying within 20m of the place of firing in each shift and a record thereof maintained in a bound paged book required to be kept maintained for the purpose as required under clause 3(c) of the permission of solid blasting granted vide this Directorate's letter no. NR-1/133 dated 27.01.2014 under the provision of Regulation 168(15), 173(a) & (c) and 175 of the Coal Mines Regulation 1957; iii) the working places including the unused working temporarily stopped been inspected and examined for ventilation and presence of inflammable gases within two hours before commencement of work in a shift and at least in every four hours during which shift continues, as required under Regulation 113(3)(b) of the Coal Mines Regulation 1957; iv) the gallery lying within 2.5m of the place of firing which was likely to be punctured, been inspected by a competent person for the presence of inflammable gas at least once in every seven days and a record thereof been maintained in a bound paged book required to be kept maintained for the purpose, as required under Regulation 143 of the Coal Mines Regulation 1957; and v) the galleries not been extended beyond 4.5m from the nearest ventilation connection without coursing of current of air up to a point within 4.5m of the face by means of a fire resistant pipes, tubes, brattices or any other material so as to ensure that the velocity of air current within 4.5m of the discontinued face is not less than 30m per minute to produce ventilation adequate to dilute gases that are inflammable or noxious so as to render them harmless, as required under the provisions of the Regulations 130(1), 146 (1) and Regulation 136A of the Coal Mines Regulation 1957; this accident could have been prevented. | U3: 76 | V3: Gas explosion / ignition | W3: 0774 Explosion/Ignition of Gas/Dust etc. | X3: Below Ground
A4: 2016 | B4: 57 | C4: 2016-04-10 | D4: 15:30 | E4: MIC JHANJHRA PROJECT | F4: EASTERN COALFIELDS LTD. | G4: Burdwan | H4: West Bengal | I4: 2 | J4: P.S.Ghosh | contract worker | Male | 43; M.Kanakaiah | Contract worker | Male | 61 | M4: closed oil drum (gas cutting) | N4: surface of underground mine | O4: gas cutting / welding | S4: While a welder was cutting a closed metallic empty hydraulic oil drum with his helper by gas cutting on the surface of an underground mine, the accumulated gas inside the drum exploded resulting into serious bodily and burn injuries to him and burn injuries to his helper to which both of them died after three and five days respectively while under medical treatment at hospital. | U4: 77 | V4: Gas explosion / ignition | W4: 0778 Other Combustible Material | X4: Above Ground
A5: 2016 | B5: 29 | C5: 2016-06-02 | D5: 19:30 | E5: KHADIA PROJECT | F5: NORTHERN COALFIELDS LTD. | G5: Sonebhadra | H5: Uttar Pradesh | I5: 1 | J5: Md.Firoz Ansari | Cont.Worker | Male | 26 | M5: tipper diesel tank; DC wiper motor-pump | N5: tipper repair (project) | O5: repair of tipper / removing air-lock | Q5: 190 | R5: CMR 1957 | S5: While crew of 3 persons was trying to remove air-lock from fuel-line of a volvo tipper, a non-submersible 12v DC battery connected wiper motor-pump was put inside its diesel tank whose un-insulated connections resulted in a spark to ignite the fuel-air mixture in the fuel tank. The fire which billowed out from fuel-tank cap resulted serious burn injuries to one helper and minor burn injuries to two other persons. The helper succumbed to his injuries after 10 days while undergoing treatment at hospital. | T5: Had, i) the non-submersible wiper motor-pump with naked/un-insulated connection not been used to pump fuel from fuel tank to the fuel-line of the tipper as to remove the air lock, thus negligently not endangering life and safety of the persons employed in repair of the tipper, as called for by the provisions of regulation 190 of coal mines regulations 1957, and, ii) competent persons been deputed for carrying out repairs on the tipper, all concerned with the repair and maintenance of HEMM deployed in the mine been provided with written safe work procedures, and all activities being carried on by the contractors been monitored to ensure that all the requirements of statute and procedures related to safety were compiled with, thus negligently not endangering life and safety of the persons employed in repair of the tipper, as called for by the provisions of regulation 190 of coal mines regulations 1957, read with DGMS circular no. tech 1 of 2008 & no. tech.9 of 2008, this accident could have been averted. | U5: 63 | V5: Vehicle / machinery fire | W5: 0335 Dumpers | X5: Opencast
A6: 2016 | B6: 40 | C6: 2016-09-30 | D6: 23:15 | E6: GAZLITAND | F6: BHARAT COKING COAL LTD. | G6: Dhanbad | H6: Jharkhand | I6: 1 | J6: Sahdeo P. Yadav | dumper optr. | Male | 43 | K6: 11 | M6: water tanker; coal dump fire | N6: coal dump (opencast) | O6: travelling to quench dump fire | P6: Yes | Q6: 38(1)(a); 43(1)(c); 42(1); 190 | R6: CMR 1957 | S6: While a water tanker was enroute to top of a coal dump in an open cast coal mine to sprinkle water to quench fire at its toe, tanker engine got deprived of supply of fuel due to less fuel in the tank resulting in malfunctioning of steering thus driver could not control the tanker and it toppled down from a height of 11m throwing driver off the seat, received serious bodily injuries to which he succumbed on the way to hospital. | T6: Had, i) the water tanker driver toped up diesel in tanker to prevent air lock and malfunctioning of steering and negligently not omitted to put on seat belt thereby not endangered his own life, ii) the top of coal dump no.5 been inspected and examined by Overman and ACM for existence of its berm and condition of sides prior to engage the water tanker driver to deal with fire by pouring water from top and iii) water tanker driver not been deployed to pour water by water tanker from top of the dump to quench coal dump fire as required under the provisions of Reg. 38(1)(a), 43(1)(c), (e) & (8)(a), 42(1)&(2) and 190 of the CMR, 1957, this accident could have been averted. | U6: 68 | V6: Hot strata / dump fire | W6: 0339 Wheeled Trackless(Truck,Tanker,etc.) | X6: Opencast
A7: 2017 | B7: 49 | C7: 2017-05-04 | E7: CHIRIMIRI | F7: SOUTH EASTERN COALFIELDS LTD. | G7: Korea | H7: Chhattisgarh | I7: 1 | J7: Roshanlal | Contractor Worker | Male | 40 | K7: 10 | L7: 6m from toe of bench | M7: hot bench material, ash and steam | N7: opencast bench | O7: fire quenching (water jet) | P7: Yes | Q7: 101(1); 98(1) | R7: CMR 1957 | S7: While a contractor worker was quenching fire in coal bench by water jet standing at a distance of about 6m from the toe of bench in night shift of an open cast coal mine, suddenly hot material of the bench slide from a height of about 10 m forming a cloud of hot ash and steam, causing severe burn injuries to which he succumbed after 8 days in hospital. Two dumper operators standing nearby in wind direction escaped with reportable burn injuries. | T7: Had, Quenching of fire with water jet not been done on the coal bench on fire standing near toe of the bench without proper supervision and code of safe practice framed for the workers deployed for firefighting been implemented as per clause VI 24.0 (c) in Annexure I of the permission renewed vide letter no 1571 dated 20.06.2012 under Regulations 101(1), 98(1) & (3) of the CMR 1957, this accident could have been averted. | U7: 116 | V7: Hot strata / dump fire | W7: 0779 Other Accidents due to Dust/Gas/Fire | X7: Opencast
A8: 2018 | B8: 41 | C8: 2018-05-05 | D8: 10:30 | E8: DUDHICHUA PROJECT | F8: NORTHERN COALFIELDS LTD. | G8: Singrauli | H8: Madhya Pradesh | I8: 1 | J8: L. Gupta | mechanical Fitter | Male | 59 | M8: oxygen cylinder; dozer | N8: surface near coal heap | O8: dozer reversing | Q8: 239; 210(1) | R8: CMR 2017 | S8: While reversing, a dozer rolled over an oxygen cylinder kept on the surface near coal heap and caused explosion inflicting serious burn injuries to in fitter the vicinity, to which he succumbed after 24 hours during treatment in hospital. The accident could have been averted, | T8: Had, i) the operator been more vigilant and been ensured that the place for movement of dozer should be free from any object thus negligently or wilfully did thing likely to endanger life or, negligently or wilfully omitted to do thing necessary for the safety of the persons employed therein in contravention of the provision of Regulation 239 of coal Mines Regulation 2017. ii) oxygen cylinders when not in use been kept in trolley or inside fenced area where there is no movement of HEMM as to obviate any risk of fire, bursting or explosion in contraventions of the provision of Regulation 210(1) of Coal Mines Regulation 2017. | U8: 153 | V8: Gas explosion / ignition | W8: 0779 Other Accidents due to Dust/Gas/Fire | X8: Above Ground
A9: 2019 | B9: 14 | C9: 2019-02-01 | E9: NIGAHI PROJECT | F9: NORTHERN COALFIELDS LTD. | G9: Singrauli | H9: Madhya Pradesh | I9: 1 | J9: S.S. Shah | Cont. Employee | Male | 26 | L9: 18.8 m3 tipper | M9: tipper fuel tank (diesel spill) | N9: haul road junction (opencast) | O9: dumper haulage / travelling to loading face | Q9: 239 | R9: CMR 2017 | S9: While an 18.8 m3 empty tipper was on way to loading face it crashed into right side dump body of OB loaded tipper coming from the opposite direction at haul road junction thus punctured the fuel tank of loaded tipper resulting in diesel spill out to catch fire in both the tippers and empty tipper driver unable to escape as was being entrapped in damaged cabin was burned to death. | T9: Had, the empty tipper not been driven unmindfully without paying attention to signals like horn & dipper given by driver of loaded tipper coming from opposite direction to crash into it, thus not negligently endangering his own life and safety of persons employed in the mine, as called for by the provisions of Regulation 239 of the Coal Mines Regulations, 2017, this accident could have been averted. | U9: 179 | V9: Vehicle / machinery fire | W9: 0335 Dumpers | X9: Opencast
A10: 2020 | B10: 28 | C10: 2020-02-13 | D10: 02:40 | E10: JAMPALLI O/C MINE | F10: SOUTH EASTERN COALFIELDS LTD. | G10: Raigarh | H10: Chhattisgarh | I10: 1 | J10: R.K. Kushwaha | Excavator Optr | Male | 24 | M10: excavator cabin (short circuit) | N10: top of overburden bench (opencast) | O10: parked during break; operator asleep in cabin | Q10: 139(1)(d); 110; 217(1) | R10: CMR 2017 | S10: While an excavator was parked at top of overburden bench of an opencast coal mine during break period, the operator's cabin caught fire due to short circuit inflicting serious burn injuries to the operator sleeping inside the cabin, who succumbed to injuries during treatment at hospital after five days. | T10: Had, i) the excavator been provided with Automatic fire Detection and Suppression System, as required under the provisions of Regulations 139(1)(d) of the Coal Mines Regulations, 2017; ii) the excavator been inspected and tested in the beginning of the shift about various systems, sub-systems and protective devices and cabin been kept clean and free from any inflammable material as stipulated in codes of practices prepared under Regulation 110 of the Coal Mines Regulations, 2017; iii) the excavator been free from patent defect (i.e., alternation in design by connecting additional cable with joints from the battery) and maintained properly for safe operation, as required under the provision of Regulations 217(1) of the Coal Mines Regulations, 2017; this accident could have been averted. | U10: 223 | V10: Vehicle / machinery fire | W10: 0448 Other Heavy Earth Moving Machinery | X10: Opencast
A11: 2021 | B11: 7 | C11: 2021-01-13 | D11: 13:30 | E11: BHOWRA(SOUTH) | F11: BHARAT COKING COAL LTD. | G11: Dhanbad | H11: Jharkhand | I11: 1 | J11: Baban Singh | Canteen Boy | Male | 30 | K11: 30 | L11: about 54 Cu. m | M11: hot overburden | N11: toe of hot overburden dump (opencast) | O11: present in unsafe area below hot dump | P11: Yes | Q11: 112(1); 196(3); 128(7); 39(1)(c) | R11: CMR 2017 | S11: While two contractual persons were present in unsafe area below dumped hot overburden of height about 30m, of an opencast coal mine, suddenly about 54 Cu. m of hot overburden slide from top in which both were entrapped and received burn injuries, causing death of one person after about 25 Hrs. 30 minutes during treatment and the other survived with disability. | T11: Had, the hot overburden been quenched with water, the unsafe area been kept securely fenced and the deceased been trained as required under Condition 15.2 of permission granted vide letter no. R-3/010157/P-24/Reg. 112(1) & 196(3)/2019/18, dated 07.01.2020 read with Regulation 128(7) of the Coal Mines Regulations, 2017, Regulation 39(1)(c) of the Coal Mines Regulations, 2017 and Rule 6 of the Mines Vocational Training Rules, 1966, this accident could have been averted. | U11: 250 | V11: Hot strata / dump fire | W11: 0112 Fall of Sides (Other than Overhangs) | X11: Opencast
A12: 2021 | B12: 10 | C12: 2021-12-31 | D12: 16:45 | E12: NEW KENDA | F12: EASTERN COALFIELDS LTD. | G12: Burdwan | H12: West Bengal | I12: 1 | J12: Ajoy Kr.Mukherjee | Sr.Overman | Male | 59 | K12: 50 | M12: fly ash fill; hot pothole | N12: fly ash filling area (fire-affected ground) | O12: supervision of fly ash filling and dozing; inspecting smoke | P12: Yes | Q12: 37(2)(c)(h); 104(1)(5)(e); 252(1)(2)(e)(j); 43(7); 47(3); 239 | R12: CMR 2017 | S12: While a Senior Overman was engaged for supervision of fly ash filling and dozing operation at the unstable and cracks formed ground, in the meantime he saw smoke coming out at a distance of 50m from fly ash filling area, subsequently he went there on foot to inspect the smoke coming out from newly formed crack, suddenly a pothole was occurred just beneath his feet where he was standing and inspecting the place resulting he fell inside the hot pot hole and body was not recovered till date. | T12: Had, the necessary measures been taken to eliminate or minimise the risk of formation of potholes and subsidence to maintain the stability of the ground for the safety and health of persons employed in the mine as required under the provision of Regulation 37(2)(c)(h) of the Coal Mine Regulation, 2017 the risk assessment exercise been carried out and implemented for the hazard of potholes subsidence and site-specific SOPs were framed for stabilization work for filling of pot holes in subsidence prone areas and handed over to concerned persons as required under the provisions of Regulation 104(1)(5)(e) of the Coal Mine Regulation,2017, the emergency response and evacuation plan been properly prepared to use in the case of mine emergencies such as mine fires, explosions and implemented when potholes and subsidence occurred and the procedures clearly framed including special training been imparted to persons supervisors to respond to critical operations such as filling of hot pot holes and subsided areas and mock rehearsals conducted at regular intervals required under the provision of Regulation 252(1)(2)(e)(j) of the Coal Mine Regulation,2017. the supervisor been provided with a plan or tracing showing the position of workings below ground which are prone to potholes and subsidence to prevent inadvertent entry of supervisors un-knowingly in the unstable areas for inspections required under the provisions of Regulation43(7) of the Coal Mine Regulation, 2017. the pot hole and subsidence area been examined carefully while entering in to the area taken reasonable care for his own safety while inspection and thus negligently omitted to do anything to endanger life for the safety of himself as required under the Regulation 47(3) and Regulation 239 of Coal Mines Regulations,2017 the accident could have been averted. | U12: 251 | V12: Hot strata / dump fire | W12: 0117 Subsidence | X12: Above Ground
A13: 2022 | B13: 5 | C13: 2022-02-20 | D13: 09:00 | E13: ROCP/SOUTH JHARIA | F13: BHARAT COKING COAL LTD. | G13: Dhanbad | H13: Jharkhand | I13: 1 | J13: Shivram Kumbhakar | Excav.Operator | Male | 39 | K13: 11 | L13: 11m high, 55 degree slope | M13: heated material; excavator cabin | N13: in-pit waste dump bench (opencast) | O13: cleaning / levelling haul road near toe | P13: Yes | Q13: 106(4); 108(2); 138(1); 47(2)(b); 39(1) | R13: CMR 2017 | S13: While a excavator was deployed for cleaning and levelling haul road near toe of the bench made in the in-pit waster dump of height 11m & slope 55 degree having fire in an opencast coal mine, a chunk of heated material roll down from the bench and fragmented heated limp pieces pierced in to the operator cabin by breaking over portion of the front glass, causing burn injury to the operator who succumbed while undergoing treatment at a hospital after three and half days of the accident. | T13: Had, i. the height of the bench not been exceeded three meters as required under the provision of the Regulation 106(4) of the Coal Mines Regulations, 2017; ii. the slope of the bench not been exceeded 37.5 degree from the horizontal as required under the provision of the Regulation 108(2) of the Coal Mines Regulations, 2017; iii. effective steps been taken without delay to deal with the fire and the excavator not been deployed at the toe of the bench known to have fire as required under the provision of the Regulations 138(1)&(2) of the Coal Mines Regulations, 2017; iv. the place been inspected by statutory personnel before deployment of excavator and necessary directions been given to ensure safety of the persons employed therein as required under the provisions of the Regulations 47(2)(b)&(3) of the Coal Mines Regulations, 2017 and v. effective ongoing communication and co-ordination between mine officials been established by the contractor for identifying hazards and taking measures to eliminate and control risk, arrangements for reporting injuries been ensured and workplace safety awareness been provided to work persons prior to commencement of work as required under the provision of the Regulation 39(1) of the Coal Mines regulations, 2017; this accident could have been averted. | U13: 286 | V13: Hot strata / dump fire | W13: 0112 Fall of Sides (Other than Overhangs) | X13: Opencast
A14: 2022 | B14: 24 | C14: 2022-05-07 | D14: 08:30 | E14: BARTARAI | F14: SOUTH EASTERN COALFIELDS LTD. | G14: Anuppur | H14: Madhya Pradesh | I14: 1 | J14: Ramkali | Lamp Fitter | Female | 56 | M14: flame safety lamp; fuel-soaked wiping cloth; saree | N14: lamp room (surface) | O14: igniting flame safety lamp | Q14: 40(4)(a); 239; 179(7) | R14: CMR 2017 | S14: While a female lamp fitter was igniting a flame safety lamp, suddenly the burning match stick dropped on a wiping cloth, partially soaked with fuel, causing fire on it which incidentally initiated fire on her saree (due to fall of fired wiping cloth) sustaining serious burn injury which proved fatal after 12 days in the hospital during treatment. | T14: Had, (i) reasonable care been taken for safety during igniting the flame safety lamp including proper care and use of protective clothing (not wearing synthetic saree) as required under Reg.40(4)(a) of Coal Mines Regulations,2017 (ii) the works of igniting flame safety lamp and cleaning, refilling, refitting etc., been done on separate table, thereby wilfully or negligently endangered the safety of persons engaged in the job as required under reg.239 of Coal Mines Regrlations,2017 (iii) a competent person holding Manager's, Overman's or Gas Testing certificate been appointed for maintenance and examination of safety lamp as required under Regulation 179(7) of the Coal Mines Regulations, 2017 this accident could have been averted. | U14: 298 | V14: Personal burn injury | W14: 0999 Unclassified | X14: Above Ground
A15: 2022 | B15: 17 | C15: 2022-06-24 | D15: 13:45 | E15: SELECTED DHORI QRY.NO.1 (KALYANI PROJ.) | F15: CENTRAL COALFIELDS LTD. | G15: Bokaro | H15: Jharkhand | I15: 1 | J15: Mahendra Yadav | Cont. Employee | Male | 32 | K15: 11 | L15: 11m high, 72 degree slope | M15: heated material; excavator cabin | N15: old overburden dump bench (opencast) | O15: overburden loading by excavator | P15: Yes | Q15: 239; 110(4); 106(4); 108(2); 138(1) | R15: CMR 2017 | S15: While an excavator was deployed for loading of overburden from an old overburden dump of about 11m in height and sloped at about 72 degrees having fire in remnant rib of coal seam about 2.5-3.5m thickness in an opencast coal mine, a chunk of heated material roll down from the highwall side of the bench and broken hot lumps pierced in to the operator cabin by breaking the front glass, causing burn injury to the operator to which he succumbed on the spot. | T15: Had, i) the excavator not been deployed very close to the highwall of the bench in an old overburden dump having fire thus not negligently endangering his own life as required under the provision of the Regulation 239 of the Coal Mines Regulations, 2017; ii) the codes of practice framed to work near fire affected area been strictly enforced as required under the provision of the Regulation 110 (4) of the Coal Mines Regulations,2017; iii) the height of the bench in an old overburden dump not been exceeded three meters as required under the provision of the Regulation 106 (4) of the Coal Mines Regulations, 2017; iv) the slope of the bench in an old overburden dump not been exceeded 37.5 degrees from the horizontal as required under the provision of the Regulation 108 (2) of the Coal Mines Regulations, 2017 and v) an effective steps been taken without delay to deal with the fire or heating in an old overburden dump and the excavator not been deployed at the toe of the bench until fire or heating was extinguished as required under the provision of the Regulations 138 (1) & (2) of the Coal Mines Regulations, 2017. this accident could have been averted. | U15: 293 | V15: Hot strata / dump fire | W15: 0779 Other Accidents due to Dust/Gas/Fire | X15: Opencast
A16: 2022 | B16: 7 | C16: 2022-08-11 | D16: 02:15 | E16: BHOWRA(SOUTH) | F16: BHARAT COKING COAL LTD. | G16: Dhanbad | H16: Jharkhand | I16: 2 | J16: G.C. Mahto | Pump Optr | Male | 54; H.S. Gorh | Pump Optr. | Male | 59 | K16: 70.4 | L16: about 154.72 Cu.m; pump 14m from toe | M16: hot strata | N16: pump station near toe (opencast) | O16: pump station duty during heavy rain | P16: Yes | Q16: 104(1)(b); 239; 43(11); 45(1); 54(a); 54(d); 48(3) | R16: CMR 2017 | S16: While four workmen were engaged at a pump station at a distance of about 14m from the toe of side of an opencast coal mine, having fiery strata; about 154.72 Cu.m of hot strata dislodged from a height of about 70.40m during heavy rain, emanating cloud of steam and hot ash causing burn injuries to them; to which one of them succumbed in hospital next day, another succumbed in hospital after twelve days and remaining two joined duty after recovery. | T16: Had, (1) the pump station not been negligently kept at an unsafe location without assessing the risk to safety of workmen to which they were exposed while at work, as required under the Regulation 104(1)(b), Regulation 239 read with Regulations 43(11), 45(1), 54(a) and 54(d) of the Coal Mines Regulations, 2017, and (2) the workmen been timely withdrawn from the pump station where there was serious danger to their life due to fire and during heavy rain, as required under the Regulation 48(3) of the Coal Mines Regulations, 2017, this accident could have been averted. | U16: 287 | V16: Hot strata / dump fire | W16: 0112 Fall of Sides (Other than Overhangs) | X16: Opencast
A17: 2022 | B17: 18 | C17: 2022-11-27 | D17: 09:30 | E17: DIPKA MINE NO.IA | F17: SOUTH EASTERN COALFIELDS LTD. | G17: Korba | H17: Chhattisgarh | I17: 1 | J17: Paras Ram Yadav | Contractor worker | Male | 35 | M17: hot ash (ramp on fire) | N17: old ramp / bottom bench (opencast) | O17: carrying water hose pipe (fire fighting) | P17: Yes | S17: While a contractor worker was trying to bring a water hose pipe from top of the old ramp to bottom bench, slipped from the edge of the ramp and fell on hot ash at the bottom edge of ramp on fire, inflicted burn injury which resulted into fatality during the treatment at the hospital. | T17: Had, i. the deceased been accompanied by the co-worker/supervisor at the remote place of work, ii. the deceased been properly trained in firefighting work, iii. the deceased been wearing proper PPE and Fire protective cloth during firefighting work. this accident could have been averted. | U17: 294 | V17: Hot strata / dump fire | W17: 0779 Other Accidents due to Dust/Gas/Fire | X17: Opencast

Sheet Fire Stats 2016-22
A1: Dust, gas and other combustible material accidents by year and place - Coal mines
A2: Source: Statement 3.2, 4.2, 5.2, 6.2, 7.2, 8.2, 9.2 (by place and detailed cause), row 'TOTAL : DUST, GAS & OTHER COMBUSTIBLE MATERIAL'. Years with no row printed are zero. Total rows are formulas. This is the report's own category; it is not the same as the fire register.
A4: Year | B4: Place | C4: Fatal accidents | D4: Persons killed | E4: Seriously injured in fatal accidents | F4: Serious accidents | G4: Seriously injured in serious accidents | H4: Total persons seriously injured
A5: 2016 | B5: Below Ground | C5: 2 | D5: 2 | E5: 0 | F5: 0 | G5: 0 | H5: =E5+G5 -> 0
A6: 2016 | B6: Opencast | C6: 1 | D6: 1 | E6: 0 | F6: 0 | G6: 0 | H6: =E6+G6 -> 0
A7: 2016 | B7: Above Ground | C7: 1 | D7: 2 | E7: 0 | F7: 0 | G7: 0 | H7: =E7+G7 -> 0
A8: 2016 | B8: Total | C8: =SUM(C5:C7) -> 4 | D8: =SUM(D5:D7) -> 5 | E8: =SUM(E5:E7) -> 0 | F8: =SUM(F5:F7) -> 0 | G8: =SUM(G5:G7) -> 0 | H8: =E8+G8 -> 0
A9: 2017 | B9: Below Ground | C9: 0 | D9: 0 | E9: 0 | F9: 0 | G9: 0 | H9: =E9+G9 -> 0
A10: 2017 | B10: Opencast | C10: 1 | D10: 1 | E10: 0 | F10: 0 | G10: 0 | H10: =E10+G10 -> 0
A11: 2017 | B11: Above Ground | C11: 0 | D11: 0 | E11: 0 | F11: 0 | G11: 0 | H11: =E11+G11 -> 0
A12: 2017 | B12: Total | C12: =SUM(C9:C11) -> 1 | D12: =SUM(D9:D11) -> 1 | E12: =SUM(E9:E11) -> 0 | F12: =SUM(F9:F11) -> 0 | G12: =SUM(G9:G11) -> 0 | H12: =E12+G12 -> 0
A13: 2018 | B13: Below Ground | C13: 1 | D13: 3 | E13: 0 | F13: 0 | G13: 0 | H13: =E13+G13 -> 0
A14: 2018 | B14: Opencast | C14: 0 | D14: 0 | E14: 0 | F14: 0 | G14: 0 | H14: =E14+G14 -> 0
A15: 2018 | B15: Above Ground | C15: 1 | D15: 1 | E15: 0 | F15: 0 | G15: 0 | H15: =E15+G15 -> 0
A16: 2018 | B16: Total | C16: =SUM(C13:C15) -> 2 | D16: =SUM(D13:D15) -> 4 | E16: =SUM(E13:E15) -> 0 | F16: =SUM(F13:F15) -> 0 | G16: =SUM(G13:G15) -> 0 | H16: =E16+G16 -> 0
A17: 2019 | B17: Below Ground | C17: 0 | D17: 0 | E17: 0 | F17: 0 | G17: 0 | H17: =E17+G17 -> 0
A18: 2019 | B18: Opencast | C18: 0 | D18: 0 | E18: 0 | F18: 0 | G18: 0 | H18: =E18+G18 -> 0
A19: 2019 | B19: Above Ground | C19: 0 | D19: 0 | E19: 0 | F19: 0 | G19: 0 | H19: =E19+G19 -> 0
A20: 2019 | B20: Total | C20: =SUM(C17:C19) -> 0 | D20: =SUM(D17:D19) -> 0 | E20: =SUM(E17:E19) -> 0 | F20: =SUM(F17:F19) -> 0 | G20: =SUM(G17:G19) -> 0 | H20: =E20+G20 -> 0
A21: 2020 | B21: Below Ground | C21: 0 | D21: 0 | E21: 0 | F21: 0 | G21: 0 | H21: =E21+G21 -> 0
A22: 2020 | B22: Opencast | C22: 0 | D22: 0 | E22: 0 | F22: 0 | G22: 0 | H22: =E22+G22 -> 0
A23: 2020 | B23: Above Ground | C23: 0 | D23: 0 | E23: 0 | F23: 0 | G23: 0 | H23: =E23+G23 -> 0
A24: 2020 | B24: Total | C24: =SUM(C21:C23) -> 0 | D24: =SUM(D21:D23) -> 0 | E24: =SUM(E21:E23) -> 0 | F24: =SUM(F21:F23) -> 0 | G24: =SUM(G21:G23) -> 0 | H24: =E24+G24 -> 0
A25: 2021 | B25: Below Ground | C25: 0 | D25: 0 | E25: 0 | F25: 0 | G25: 0 | H25: =E25+G25 -> 0
A26: 2021 | B26: Opencast | C26: 0 | D26: 0 | E26: 0 | F26: 0 | G26: 0 | H26: =E26+G26 -> 0
A27: 2021 | B27: Above Ground | C27: 0 | D27: 0 | E27: 0 | F27: 0 | G27: 0 | H27: =E27+G27 -> 0
A28: 2021 | B28: Total | C28: =SUM(C25:C27) -> 0 | D28: =SUM(D25:D27) -> 0 | E28: =SUM(E25:E27) -> 0 | F28: =SUM(F25:F27) -> 0 | G28: =SUM(G25:G27) -> 0 | H28: =E28+G28 -> 0
A29: 2022 | B29: Below Ground | C29: 1 | D29: 1 | E29: 0 | F29: 0 | G29: 0 | H29: =E29+G29 -> 0
A30: 2022 | B30: Opencast | C30: 1 | D30: 1 | E30: 0 | F30: 0 | G30: 0 | H30: =E30+G30 -> 0
A31: 2022 | B31: Above Ground | C31: 0 | D31: 0 | E31: 0 | F31: 0 | G31: 0 | H31: =E31+G31 -> 0
A32: 2022 | B32: Total | C32: =SUM(C29:C31) -> 2 | D32: =SUM(D29:D31) -> 2 | E32: =SUM(E29:E31) -> 0 | F32: =SUM(F29:F31) -> 0 | G32: =SUM(G29:G31) -> 0 | H32: =E32+G32 -> 0
A34: All years 2016-2022
A35: 2016-2022 | B35: Below Ground | C35: =SUMIFS(C$5:C$32,$B$5:$B$32,$B35) -> 4 | D35: =SUMIFS(D$5:D$32,$B$5:$B$32,$B35) -> 6 | E35: =SUMIFS(E$5:E$32,$B$5:$B$32,$B35) -> 0 | F35: =SUMIFS(F$5:F$32,$B$5:$B$32,$B35) -> 0 | G35: =SUMIFS(G$5:G$32,$B$5:$B$32,$B35) -> 0 | H35: =E35+G35 -> 0
A36: 2016-2022 | B36: Opencast | C36: =SUMIFS(C$5:C$32,$B$5:$B$32,$B36) -> 3 | D36: =SUMIFS(D$5:D$32,$B$5:$B$32,$B36) -> 3 | E36: =SUMIFS(E$5:E$32,$B$5:$B$32,$B36) -> 0 | F36: =SUMIFS(F$5:F$32,$B$5:$B$32,$B36) -> 0 | G36: =SUMIFS(G$5:G$32,$B$5:$B$32,$B36) -> 0 | H36: =E36+G36 -> 0
A37: 2016-2022 | B37: Above Ground | C37: =SUMIFS(C$5:C$32,$B$5:$B$32,$B37) -> 2 | D37: =SUMIFS(D$5:D$32,$B$5:$B$32,$B37) -> 3 | E37: =SUMIFS(E$5:E$32,$B$5:$B$32,$B37) -> 0 | F37: =SUMIFS(F$5:F$32,$B$5:$B$32,$B37) -> 0 | G37: =SUMIFS(G$5:G$32,$B$5:$B$32,$B37) -> 0 | H37: =E37+G37 -> 0
A38: 2016-2022 | B38: Total | C38: =SUMIFS(C$5:C$32,$B$5:$B$32,$B38) -> 9 | D38: =SUMIFS(D$5:D$32,$B$5:$B$32,$B38) -> 12 | E38: =SUMIFS(E$5:E$32,$B$5:$B$32,$B38) -> 0 | F38: =SUMIFS(F$5:F$32,$B$5:$B$32,$B38) -> 0 | G38: =SUMIFS(G$5:G$32,$B$5:$B$32,$B38) -> 0 | H38: =E38+G38 -> 0

Sheet Fire by Place 2016-22
A1: Fire-related fatal accidents by year and place - Coal mines (fire register)
A2: Source: 'Fire Accidents' sheet (16 fatal accidents, counted by formula). Place is classified from the narrative (column X). Total rows are formulas.
A4: Year | B4: Place | C4: Fatal accidents | D4: Persons killed
A5: 2016 | B5: Below Ground | C5: =COUNTIFS('Fire Accidents'!$A$2:$A$17,$A5,'Fire Accidents'!$X$2:$X$17,$B5) -> 1 | D5: =SUMIFS('Fire Accidents'!$I$2:$I$17,'Fire Accidents'!$A$2:$A$17,$A5,'Fire Accidents'!$X$2:$X$17,$B5) -> 1
A6: 2016 | B6: Opencast | C6: =COUNTIFS('Fire Accidents'!$A$2:$A$17,$A6,'Fire Accidents'!$X$2:$X$17,$B6) -> 3 | D6: =SUMIFS('Fire Accidents'!$I$2:$I$17,'Fire Accidents'!$A$2:$A$17,$A6,'Fire Accidents'!$X$2:$X$17,$B6) -> 3
A7: 2016 | B7: Above Ground | C7: =COUNTIFS('Fire Accidents'!$A$2:$A$17,$A7,'Fire Accidents'!$X$2:$X$17,$B7) -> 1 | D7: =SUMIFS('Fire Accidents'!$I$2:$I$17,'Fire Accidents'!$A$2:$A$17,$A7,'Fire Accidents'!$X$2:$X$17,$B7) -> 2
A8: 2016 | B8: Total | C8: =SUM(C5:C7) -> 5 | D8: =SUM(D5:D7) -> 6
A9: 2017 | B9: Below Ground | C9: =COUNTIFS('Fire Accidents'!$A$2:$A$17,$A9,'Fire Accidents'!$X$2:$X$17,$B9) -> 0 | D9: =SUMIFS('Fire Accidents'!$I$2:$I$17,'Fire Accidents'!$A$2:$A$17,$A9,'Fire Accidents'!$X$2:$X$17,$B9) -> 0
A10: 2017 | B10: Opencast | C10: =COUNTIFS('Fire Accidents'!$A$2:$A$17,$A10,'Fire Accidents'!$X$2:$X$17,$B10) -> 1 | D10: =SUMIFS('Fire Accidents'!$I$2:$I$17,'Fire Accidents'!$A$2:$A$17,$A10,'Fire Accidents'!$X$2:$X$17,$B10) -> 1
A11: 2017 | B11: Above Ground | C11: =COUNTIFS('Fire Accidents'!$A$2:$A$17,$A11,'Fire Accidents'!$X$2:$X$17,$B11) -> 0 | D11: =SUMIFS('Fire Accidents'!$I$2:$I$17,'Fire Accidents'!$A$2:$A$17,$A11,'Fire Accidents'!$X$2:$X$17,$B11) -> 0
A12: 2017 | B12: Total | C12: =SUM(C9:C11) -> 1 | D12: =SUM(D9:D11) -> 1
A13: 2018 | B13: Below Ground | C13: =COUNTIFS('Fire Accidents'!$A$2:$A$17,$A13,'Fire Accidents'!$X$2:$X$17,$B13) -> 0 | D13: =SUMIFS('Fire Accidents'!$I$2:$I$17,'Fire Accidents'!$A$2:$A$17,$A13,'Fire Accidents'!$X$2:$X$17,$B13) -> 0
A14: 2018 | B14: Opencast | C14: =COUNTIFS('Fire Accidents'!$A$2:$A$17,$A14,'Fire Accidents'!$X$2:$X$17,$B14) -> 0 | D14: =SUMIFS('Fire Accidents'!$I$2:$I$17,'Fire Accidents'!$A$2:$A$17,$A14,'Fire Accidents'!$X$2:$X$17,$B14) -> 0
A15: 2018 | B15: Above Ground | C15: =COUNTIFS('Fire Accidents'!$A$2:$A$17,$A15,'Fire Accidents'!$X$2:$X$17,$B15) -> 1 | D15: =SUMIFS('Fire Accidents'!$I$2:$I$17,'Fire Accidents'!$A$2:$A$17,$A15,'Fire Accidents'!$X$2:$X$17,$B15) -> 1
A16: 2018 | B16: Total | C16: =SUM(C13:C15) -> 1 | D16: =SUM(D13:D15) -> 1
A17: 2019 | B17: Below Ground | C17: =COUNTIFS('Fire Accidents'!$A$2:$A$17,$A17,'Fire Accidents'!$X$2:$X$17,$B17) -> 0 | D17: =SUMIFS('Fire Accidents'!$I$2:$I$17,'Fire Accidents'!$A$2:$A$17,$A17,'Fire Accidents'!$X$2:$X$17,$B17) -> 0
A18: 2019 | B18: Opencast | C18: =COUNTIFS('Fire Accidents'!$A$2:$A$17,$A18,'Fire Accidents'!$X$2:$X$17,$B18) -> 1 | D18: =SUMIFS('Fire Accidents'!$I$2:$I$17,'Fire Accidents'!$A$2:$A$17,$A18,'Fire Accidents'!$X$2:$X$17,$B18) -> 1
A19: 2019 | B19: Above Ground | C19: =COUNTIFS('Fire Accidents'!$A$2:$A$17,$A19,'Fire Accidents'!$X$2:$X$17,$B19) -> 0 | D19: =SUMIFS('Fire Accidents'!$I$2:$I$17,'Fire Accidents'!$A$2:$A$17,$A19,'Fire Accidents'!$X$2:$X$17,$B19) -> 0
A20: 2019 | B20: Total | C20: =SUM(C17:C19) -> 1 | D20: =SUM(D17:D19) -> 1
A21: 2020 | B21: Below Ground | C21: =COUNTIFS('Fire Accidents'!$A$2:$A$17,$A21,'Fire Accidents'!$X$2:$X$17,$B21) -> 0 | D21: =SUMIFS('Fire Accidents'!$I$2:$I$17,'Fire Accidents'!$A$2:$A$17,$A21,'Fire Accidents'!$X$2:$X$17,$B21) -> 0
A22: 2020 | B22: Opencast | C22: =COUNTIFS('Fire Accidents'!$A$2:$A$17,$A22,'Fire Accidents'!$X$2:$X$17,$B22) -> 1 | D22: =SUMIFS('Fire Accidents'!$I$2:$I$17,'Fire Accidents'!$A$2:$A$17,$A22,'Fire Accidents'!$X$2:$X$17,$B22) -> 1
A23: 2020 | B23: Above Ground | C23: =COUNTIFS('Fire Accidents'!$A$2:$A$17,$A23,'Fire Accidents'!$X$2:$X$17,$B23) -> 0 | D23: =SUMIFS('Fire Accidents'!$I$2:$I$17,'Fire Accidents'!$A$2:$A$17,$A23,'Fire Accidents'!$X$2:$X$17,$B23) -> 0
A24: 2020 | B24: Total | C24: =SUM(C21:C23) -> 1 | D24: =SUM(D21:D23) -> 1
A25: 2021 | B25: Below Ground | C25: =COUNTIFS('Fire Accidents'!$A$2:$A$17,$A25,'Fire Accidents'!$X$2:$X$17,$B25) -> 0 | D25: =SUMIFS('Fire Accidents'!$I$2:$I$17,'Fire Accidents'!$A$2:$A$17,$A25,'Fire Accidents'!$X$2:$X$17,$B25) -> 0
A26: 2021 | B26: Opencast | C26: =COUNTIFS('Fire Accidents'!$A$2:$A$17,$A26,'Fire Accidents'!$X$2:$X$17,$B26) -> 1 | D26: =SUMIFS('Fire Accidents'!$I$2:$I$17,'Fire Accidents'!$A$2:$A$17,$A26,'Fire Accidents'!$X$2:$X$17,$B26) -> 1
A27: 2021 | B27: Above Ground | C27: =COUNTIFS('Fire Accidents'!$A$2:$A$17,$A27,'Fire Accidents'!$X$2:$X$17,$B27) -> 1 | D27: =SUMIFS('Fire Accidents'!$I$2:$I$17,'Fire Accidents'!$A$2:$A$17,$A27,'Fire Accidents'!$X$2:$X$17,$B27) -> 1
A28: 2021 | B28: Total | C28: =SUM(C25:C27) -> 2 | D28: =SUM(D25:D27) -> 2
A29: 2022 | B29: Below Ground | C29: =COUNTIFS('Fire Accidents'!$A$2:$A$17,$A29,'Fire Accidents'!$X$2:$X$17,$B29) -> 0 | D29: =SUMIFS('Fire Accidents'!$I$2:$I$17,'Fire Accidents'!$A$2:$A$17,$A29,'Fire Accidents'!$X$2:$X$17,$B29) -> 0
A30: 2022 | B30: Opencast | C30: =COUNTIFS('Fire Accidents'!$A$2:$A$17,$A30,'Fire Accidents'!$X$2:$X$17,$B30) -> 4 | D30: =SUMIFS('Fire Accidents'!$I$2:$I$17,'Fire Accidents'!$A$2:$A$17,$A30,'Fire Accidents'!$X$2:$X$17,$B30) -> 5
A31: 2022 | B31: Above Ground | C31: =COUNTIFS('Fire Accidents'!$A$2:$A$17,$A31,'Fire Accidents'!$X$2:$X$17,$B31) -> 1 | D31: =SUMIFS('Fire Accidents'!$I$2:$I$17,'Fire Accidents'!$A$2:$A$17,$A31,'Fire Accidents'!$X$2:$X$17,$B31) -> 1
A32: 2022 | B32: Total | C32: =SUM(C29:C31) -> 5 | D32: =SUM(D29:D31) -> 6
A34: All years 2016-2022
A35: 2016-2022 | B35: Below Ground | C35: =SUMIFS(C$5:C$32,$B$5:$B$32,$B35) -> 1 | D35: =SUMIFS(D$5:D$32,$B$5:$B$32,$B35) -> 1
A36: 2016-2022 | B36: Opencast | C36: =SUMIFS(C$5:C$32,$B$5:$B$32,$B36) -> 11 | D36: =SUMIFS(D$5:D$32,$B$5:$B$32,$B36) -> 12
A37: 2016-2022 | B37: Above Ground | C37: =SUMIFS(C$5:C$32,$B$5:$B$32,$B37) -> 4 | D37: =SUMIFS(D$5:D$32,$B$5:$B$32,$B37) -> 5
A38: 2016-2022 | B38: Total | C38: =SUMIFS(C$5:C$32,$B$5:$B$32,$B38) -> 16 | D38: =SUMIFS(D$5:D$32,$B$5:$B$32,$B38) -> 18

Sheet Fire by Company
A1: Fire-related fatal accidents by company - Coal mines
A2: Source: 'Fire Accidents' sheet, counted by formula. All years combined below the year rows.
A4: Year | B4: Company (as printed) | C4: Fatal accidents | D4: Persons killed
A5: 2016 | B5: BHARAT COKING COAL LTD. | C5: =COUNTIFS('Fire Accidents'!$A$2:$A$17,$A5,'Fire Accidents'!$F$2:$F$17,$B5) -> 2 | D5: =SUMIFS('Fire Accidents'!$I$2:$I$17,'Fire Accidents'!$A$2:$A$17,$A5,'Fire Accidents'!$F$2:$F$17,$B5) -> 2
A6: 2016 | B6: EASTERN COALFIELDS LTD. | C6: =COUNTIFS('Fire Accidents'!$A$2:$A$17,$A6,'Fire Accidents'!$F$2:$F$17,$B6) -> 1 | D6: =SUMIFS('Fire Accidents'!$I$2:$I$17,'Fire Accidents'!$A$2:$A$17,$A6,'Fire Accidents'!$F$2:$F$17,$B6) -> 2
A7: 2016 | B7: NORTHERN COALFIELDS LTD. | C7: =COUNTIFS('Fire Accidents'!$A$2:$A$17,$A7,'Fire Accidents'!$F$2:$F$17,$B7) -> 1 | D7: =SUMIFS('Fire Accidents'!$I$2:$I$17,'Fire Accidents'!$A$2:$A$17,$A7,'Fire Accidents'!$F$2:$F$17,$B7) -> 1
A8: 2016 | B8: WESTERN COALFIELDS LTD. | C8: =COUNTIFS('Fire Accidents'!$A$2:$A$17,$A8,'Fire Accidents'!$F$2:$F$17,$B8) -> 1 | D8: =SUMIFS('Fire Accidents'!$I$2:$I$17,'Fire Accidents'!$A$2:$A$17,$A8,'Fire Accidents'!$F$2:$F$17,$B8) -> 1
A9: 2017 | B9: SOUTH EASTERN COALFIELDS LTD. | C9: =COUNTIFS('Fire Accidents'!$A$2:$A$17,$A9,'Fire Accidents'!$F$2:$F$17,$B9) -> 1 | D9: =SUMIFS('Fire Accidents'!$I$2:$I$17,'Fire Accidents'!$A$2:$A$17,$A9,'Fire Accidents'!$F$2:$F$17,$B9) -> 1
A10: 2018 | B10: NORTHERN COALFIELDS LTD. | C10: =COUNTIFS('Fire Accidents'!$A$2:$A$17,$A10,'Fire Accidents'!$F$2:$F$17,$B10) -> 1 | D10: =SUMIFS('Fire Accidents'!$I$2:$I$17,'Fire Accidents'!$A$2:$A$17,$A10,'Fire Accidents'!$F$2:$F$17,$B10) -> 1
A11: 2019 | B11: NORTHERN COALFIELDS LTD. | C11: =COUNTIFS('Fire Accidents'!$A$2:$A$17,$A11,'Fire Accidents'!$F$2:$F$17,$B11) -> 1 | D11: =SUMIFS('Fire Accidents'!$I$2:$I$17,'Fire Accidents'!$A$2:$A$17,$A11,'Fire Accidents'!$F$2:$F$17,$B11) -> 1
A12: 2020 | B12: SOUTH EASTERN COALFIELDS LTD. | C12: =COUNTIFS('Fire Accidents'!$A$2:$A$17,$A12,'Fire Accidents'!$F$2:$F$17,$B12) -> 1 | D12: =SUMIFS('Fire Accidents'!$I$2:$I$17,'Fire Accidents'!$A$2:$A$17,$A12,'Fire Accidents'!$F$2:$F$17,$B12) -> 1
A13: 2021 | B13: BHARAT COKING COAL LTD. | C13: =COUNTIFS('Fire Accidents'!$A$2:$A$17,$A13,'Fire Accidents'!$F$2:$F$17,$B13) -> 1 | D13: =SUMIFS('Fire Accidents'!$I$2:$I$17,'Fire Accidents'!$A$2:$A$17,$A13,'Fire Accidents'!$F$2:$F$17,$B13) -> 1
A14: 2021 | B14: EASTERN COALFIELDS LTD. | C14: =COUNTIFS('Fire Accidents'!$A$2:$A$17,$A14,'Fire Accidents'!$F$2:$F$17,$B14) -> 1 | D14: =SUMIFS('Fire Accidents'!$I$2:$I$17,'Fire Accidents'!$A$2:$A$17,$A14,'Fire Accidents'!$F$2:$F$17,$B14) -> 1
A15: 2022 | B15: BHARAT COKING COAL LTD. | C15: =COUNTIFS('Fire Accidents'!$A$2:$A$17,$A15,'Fire Accidents'!$F$2:$F$17,$B15) -> 2 | D15: =SUMIFS('Fire Accidents'!$I$2:$I$17,'Fire Accidents'!$A$2:$A$17,$A15,'Fire Accidents'!$F$2:$F$17,$B15) -> 3
A16: 2022 | B16: CENTRAL COALFIELDS LTD. | C16: =COUNTIFS('Fire Accidents'!$A$2:$A$17,$A16,'Fire Accidents'!$F$2:$F$17,$B16) -> 1 | D16: =SUMIFS('Fire Accidents'!$I$2:$I$17,'Fire Accidents'!$A$2:$A$17,$A16,'Fire Accidents'!$F$2:$F$17,$B16) -> 1
A17: 2022 | B17: SOUTH EASTERN COALFIELDS LTD. | C17: =COUNTIFS('Fire Accidents'!$A$2:$A$17,$A17,'Fire Accidents'!$F$2:$F$17,$B17) -> 2 | D17: =SUMIFS('Fire Accidents'!$I$2:$I$17,'Fire Accidents'!$A$2:$A$17,$A17,'Fire Accidents'!$F$2:$F$17,$B17) -> 2
A18: 2016-2022 | B18: All | C18: =SUM(C5:C17) -> 16 | D18: =SUM(D5:D17) -> 18
A20: All years by company (as printed)
A21: 2016-2022 | B21: BHARAT COKING COAL LTD. | C21: =COUNTIFS('Fire Accidents'!$F$2:$F$17,$B21) -> 5 | D21: =SUMIFS('Fire Accidents'!$I$2:$I$17,'Fire Accidents'!$F$2:$F$17,$B21) -> 6
A22: 2016-2022 | B22: SOUTH EASTERN COALFIELDS LTD. | C22: =COUNTIFS('Fire Accidents'!$F$2:$F$17,$B22) -> 4 | D22: =SUMIFS('Fire Accidents'!$I$2:$I$17,'Fire Accidents'!$F$2:$F$17,$B22) -> 4
A23: 2016-2022 | B23: NORTHERN COALFIELDS LTD. | C23: =COUNTIFS('Fire Accidents'!$F$2:$F$17,$B23) -> 3 | D23: =SUMIFS('Fire Accidents'!$I$2:$I$17,'Fire Accidents'!$F$2:$F$17,$B23) -> 3
A24: 2016-2022 | B24: EASTERN COALFIELDS LTD. | C24: =COUNTIFS('Fire Accidents'!$F$2:$F$17,$B24) -> 2 | D24: =SUMIFS('Fire Accidents'!$I$2:$I$17,'Fire Accidents'!$F$2:$F$17,$B24) -> 3
A25: 2016-2022 | B25: CENTRAL COALFIELDS LTD. | C25: =COUNTIFS('Fire Accidents'!$F$2:$F$17,$B25) -> 1 | D25: =SUMIFS('Fire Accidents'!$I$2:$I$17,'Fire Accidents'!$F$2:$F$17,$B25) -> 1
A26: 2016-2022 | B26: WESTERN COALFIELDS LTD. | C26: =COUNTIFS('Fire Accidents'!$F$2:$F$17,$B26) -> 1 | D26: =SUMIFS('Fire Accidents'!$I$2:$I$17,'Fire Accidents'!$F$2:$F$17,$B26) -> 1
A27: 2016-2022 | B27: Total | C27: =SUM(C21:C26) -> 16 | D27: =SUM(D21:D26) -> 18

Sheet Fire by Cause Group
A1: Fire-related fatal accidents by cause group - Coal mines
A2: Source: 'Fire Accidents' sheet, counted by formula. All years combined below the year rows.
A4: Year | B4: Cause group | C4: Fatal accidents | D4: Persons killed
A5: 2016 | B5: Gas explosion / ignition | C5: =COUNTIFS('Fire Accidents'!$A$2:$A$17,$A5,'Fire Accidents'!$V$2:$V$17,$B5) -> 2 | D5: =SUMIFS('Fire Accidents'!$I$2:$I$17,'Fire Accidents'!$A$2:$A$17,$A5,'Fire Accidents'!$V$2:$V$17,$B5) -> 3
A6: 2016 | B6: Hot strata / dump fire | C6: =COUNTIFS('Fire Accidents'!$A$2:$A$17,$A6,'Fire Accidents'!$V$2:$V$17,$B6) -> 1 | D6: =SUMIFS('Fire Accidents'!$I$2:$I$17,'Fire Accidents'!$A$2:$A$17,$A6,'Fire Accidents'!$V$2:$V$17,$B6) -> 1
A7: 2016 | B7: Vehicle / machinery fire | C7: =COUNTIFS('Fire Accidents'!$A$2:$A$17,$A7,'Fire Accidents'!$V$2:$V$17,$B7) -> 2 | D7: =SUMIFS('Fire Accidents'!$I$2:$I$17,'Fire Accidents'!$A$2:$A$17,$A7,'Fire Accidents'!$V$2:$V$17,$B7) -> 2
A8: 2017 | B8: Hot strata / dump fire | C8: =COUNTIFS('Fire Accidents'!$A$2:$A$17,$A8,'Fire Accidents'!$V$2:$V$17,$B8) -> 1 | D8: =SUMIFS('Fire Accidents'!$I$2:$I$17,'Fire Accidents'!$A$2:$A$17,$A8,'Fire Accidents'!$V$2:$V$17,$B8) -> 1
A9: 2018 | B9: Gas explosion / ignition | C9: =COUNTIFS('Fire Accidents'!$A$2:$A$17,$A9,'Fire Accidents'!$V$2:$V$17,$B9) -> 1 | D9: =SUMIFS('Fire Accidents'!$I$2:$I$17,'Fire Accidents'!$A$2:$A$17,$A9,'Fire Accidents'!$V$2:$V$17,$B9) -> 1
A10: 2019 | B10: Vehicle / machinery fire | C10: =COUNTIFS('Fire Accidents'!$A$2:$A$17,$A10,'Fire Accidents'!$V$2:$V$17,$B10) -> 1 | D10: =SUMIFS('Fire Accidents'!$I$2:$I$17,'Fire Accidents'!$A$2:$A$17,$A10,'Fire Accidents'!$V$2:$V$17,$B10) -> 1
A11: 2020 | B11: Vehicle / machinery fire | C11: =COUNTIFS('Fire Accidents'!$A$2:$A$17,$A11,'Fire Accidents'!$V$2:$V$17,$B11) -> 1 | D11: =SUMIFS('Fire Accidents'!$I$2:$I$17,'Fire Accidents'!$A$2:$A$17,$A11,'Fire Accidents'!$V$2:$V$17,$B11) -> 1
A12: 2021 | B12: Hot strata / dump fire | C12: =COUNTIFS('Fire Accidents'!$A$2:$A$17,$A12,'Fire Accidents'!$V$2:$V$17,$B12) -> 2 | D12: =SUMIFS('Fire Accidents'!$I$2:$I$17,'Fire Accidents'!$A$2:$A$17,$A12,'Fire Accidents'!$V$2:$V$17,$B12) -> 2
A13: 2022 | B13: Hot strata / dump fire | C13: =COUNTIFS('Fire Accidents'!$A$2:$A$17,$A13,'Fire Accidents'!$V$2:$V$17,$B13) -> 4 | D13: =SUMIFS('Fire Accidents'!$I$2:$I$17,'Fire Accidents'!$A$2:$A$17,$A13,'Fire Accidents'!$V$2:$V$17,$B13) -> 5
A14: 2022 | B14: Personal burn injury | C14: =COUNTIFS('Fire Accidents'!$A$2:$A$17,$A14,'Fire Accidents'!$V$2:$V$17,$B14) -> 1 | D14: =SUMIFS('Fire Accidents'!$I$2:$I$17,'Fire Accidents'!$A$2:$A$17,$A14,'Fire Accidents'!$V$2:$V$17,$B14) -> 1
A15: 2016-2022 | B15: All | C15: =SUM(C5:C14) -> 16 | D15: =SUM(D5:D14) -> 18
A17: All years by cause group
A18: 2016-2022 | B18: Hot strata / dump fire | C18: =COUNTIFS('Fire Accidents'!$V$2:$V$17,$B18) -> 8 | D18: =SUMIFS('Fire Accidents'!$I$2:$I$17,'Fire Accidents'!$V$2:$V$17,$B18) -> 9
A19: 2016-2022 | B19: Vehicle / machinery fire | C19: =COUNTIFS('Fire Accidents'!$V$2:$V$17,$B19) -> 4 | D19: =SUMIFS('Fire Accidents'!$I$2:$I$17,'Fire Accidents'!$V$2:$V$17,$B19) -> 4
A20: 2016-2022 | B20: Gas explosion / ignition | C20: =COUNTIFS('Fire Accidents'!$V$2:$V$17,$B20) -> 3 | D20: =SUMIFS('Fire Accidents'!$I$2:$I$17,'Fire Accidents'!$V$2:$V$17,$B20) -> 4
A21: 2016-2022 | B21: Personal burn injury | C21: =COUNTIFS('Fire Accidents'!$V$2:$V$17,$B21) -> 1 | D21: =SUMIFS('Fire Accidents'!$I$2:$I$17,'Fire Accidents'!$V$2:$V$17,$B21) -> 1
A22: 2016-2022 | B22: Total | C22: =SUM(C18:C21) -> 16 | D22: =SUM(D18:D21) -> 18

Sheet Fire Occurrences 2013-22
A1: Fire-related dangerous occurrences by year - Coal mines
A2: Source: Table 2.6 (cause wise trend in dangerous occurrences). Fire-related total and share are formulas. Ignition of inflammable gas is shown but not included in the fire-related total.
A4: Year | B4: Spontaneous heating: underground | C4: Spontaneous heating: surface | D4: Spontaneous heating: opencast | E4: Fire underground from spontaneous heating | F4: Fire underground from other causes | G4: Fire in quarry from other causes | H4: Fire on surface from other causes | I4: Fire-related total | J4: Ignition of inflammable gas (not in total) | K4: All dangerous occurrences | L4: Fire share of all occurrences
A5: 2013 | B5: 4 | C5: 3 | D5: 2 | E5: 1 | F5: 0 | G5: 1 | H5: 2 | I5: =SUM(B5:H5) -> 13 | J5: 0 | K5: 47 | L5: =IF(K5=0,0,I5/K5) -> 0.27659574
A6: 2014 | B6: 2 | C6: 0 | D6: 0 | E6: 0 | F6: 0 | G6: 0 | H6: 2 | I6: =SUM(B6:H6) -> 4 | J6: 1 | K6: 55 | L6: =IF(K6=0,0,I6/K6) -> 0.072727273
A7: 2015 | B7: 0 | C7: 7 | D7: 0 | E7: 0 | F7: 0 | G7: 1 | H7: 2 | I7: =SUM(B7:H7) -> 10 | J7: 0 | K7: 31 | L7: =IF(K7=0,0,I7/K7) -> 0.32258065
A8: 2016 | B8: 2 | C8: 0 | D8: 0 | E8: 0 | F8: 0 | G8: 1 | H8: 2 | I8: =SUM(B8:H8) -> 5 | J8: 1 | K8: 19 | L8: =IF(K8=0,0,I8/K8) -> 0.26315789
A9: 2017 | B9: 3 | C9: 0 | D9: 1 | E9: 0 | F9: 0 | G9: 0 | H9: 4 | I9: =SUM(B9:H9) -> 8 | J9: 1 | K9: 26 | L9: =IF(K9=0,0,I9/K9) -> 0.30769231
A10: 2018 | B10: 0 | C10: 0 | D10: 1 | E10: 0 | F10: 1 | G10: 0 | H10: 8 | I10: =SUM(B10:H10) -> 10 | J10: 2 | K10: 24 | L10: =IF(K10=0,0,I10/K10) -> 0.41666667
A11: 2019 | B11: 1 | C11: 0 | D11: 0 | E11: 0 | F11: 0 | G11: 0 | H11: 2 | I11: =SUM(B11:H11) -> 3 | J11: 0 | K11: 8 | L11: =IF(K11=0,0,I11/K11) -> 0.375
A12: 2020 | B12: 1 | C12: 0 | D12: 1 | E12: 0 | F12: 0 | G12: 0 | H12: 2 | I12: =SUM(B12:H12) -> 4 | J12: 1 | K12: 20 | L12: =IF(K12=0,0,I12/K12) -> 0.2
A13: 2021 | B13: 2 | C13: 0 | D13: 0 | E13: 0 | F13: 1 | G13: 0 | H13: 5 | I13: =SUM(B13:H13) -> 8 | J13: 0 | K13: 15 | L13: =IF(K13=0,0,I13/K13) -> 0.53333333
A14: 2022 | B14: 1 | C14: 0 | D14: 0 | E14: 0 | F14: 0 | G14: 3 | H14: 2 | I14: =SUM(B14:H14) -> 6 | J14: 0 | K14: 33 | L14: =IF(K14=0,0,I14/K14) -> 0.18181818
A15: 2013-2022 | B15: =SUM(B5:B14) -> 16 | C15: =SUM(C5:C14) -> 10 | D15: =SUM(D5:D14) -> 5 | E15: =SUM(E5:E14) -> 1 | F15: =SUM(F5:F14) -> 2 | G15: =SUM(G5:G14) -> 6 | H15: =SUM(H5:H14) -> 31 | I15: =SUM(I5:I14) -> 71 | ... K15: =SUM(K5:K14) -> 278 | L15: =IF(K15=0,0,I15/K15) -> 0.25539568

Sheet Fire vs All 2013-22
A1: Dust, gas and other combustible material compared with all accidents, 2013-2022 - Coal mines
A2: Sources: Table 2.7 (all fatal and serious), Table 2.9 (fatal by cause), Table 2.10 (serious by cause). 'Seriously injured' counts persons injured in serious accidents only, in both blocks, so shares are like for like.
A4: Year | B4: All causes: fatal accidents | C4: All causes: persons killed | D4: All causes: serious accidents | E4: All causes: persons seriously injured | F4: Dust/gas/combustible: fatal accidents | G4: Dust/gas/combustible: persons killed | H4: Dust/gas/combustible: serious accidents | I4: Dust/gas/combustible: persons seriously injured | J4: Share of fatal accidents | K4: Share of persons killed | L4: Share of serious accidents | M4: Share of persons seriously injured
A5: 2013 | B5: 77 | C5: 82 | D5: 456 | E5: 457 | F5: 0 | G5: 0 | H5: 0 | I5: 0 | J5: =IF(B5=0,0,F5/B5) -> 0 | K5: =IF(C5=0,0,G5/C5) -> 0 | L5: =IF(D5=0,0,H5/D5) -> 0 | M5: =IF(E5=0,0,I5/E5) -> 0
A6: 2014 | B6: 59 | C6: 62 | D6: 379 | E6: 391 | F6: 1 | G6: 1 | H6: 2 | I6: 2 | J6: =IF(B6=0,0,F6/B6) -> 0.016949153 | K6: =IF(C6=0,0,G6/C6) -> 0.016129032 | L6: =IF(D6=0,0,H6/D6) -> 0.0052770449 | M6: =IF(E6=0,0,I6/E6) -> 0.0051150895
A7: 2015 | B7: 54 | C7: 55 | D7: 302 | E7: 307 | F7: 0 | G7: 0 | H7: 1 | I7: 1 | J7: =IF(B7=0,0,F7/B7) -> 0 | K7: =IF(C7=0,0,G7/C7) -> 0 | L7: =IF(D7=0,0,H7/D7) -> 0.0033112583 | M7: =IF(E7=0,0,I7/E7) -> 0.003257329
A8: 2016 | B8: 67 | C8: 94 | D8: 269 | E8: 272 | F8: 4 | G8: 5 | H8: 0 | I8: 0 | J8: =IF(B8=0,0,F8/B8) -> 0.059701493 | K8: =IF(C8=0,0,G8/C8) -> 0.053191489 | L8: =IF(D8=0,0,H8/D8) -> 0 | M8: =IF(E8=0,0,I8/E8) -> 0
A9: 2017 | B9: 56 | C9: 61 | D9: 266 | E9: 272 | F9: 1 | G9: 1 | H9: 0 | I9: 0 | J9: =IF(B9=0,0,F9/B9) -> 0.017857143 | K9: =IF(C9=0,0,G9/C9) -> 0.016393443 | L9: =IF(D9=0,0,H9/D9) -> 0 | M9: =IF(E9=0,0,I9/E9) -> 0
A10: 2018 | B10: 49 | C10: 62 | D10: 265 | E10: 268 | F10: 2 | G10: 4 | H10: 0 | I10: 0 | J10: =IF(B10=0,0,F10/B10) -> 0.040816327 | K10: =IF(C10=0,0,G10/C10) -> 0.064516129 | L10: =IF(D10=0,0,H10/D10) -> 0 | M10: =IF(E10=0,0,I10/E10) -> 0
A11: 2019 | B11: 51 | C11: 56 | D11: 193 | E11: 198 | F11: 0 | G11: 0 | H11: 0 | I11: 0 | J11: =IF(B11=0,0,F11/B11) -> 0 | K11: =IF(C11=0,0,G11/C11) -> 0 | L11: =IF(D11=0,0,H11/D11) -> 0 | M11: =IF(E11=0,0,I11/E11) -> 0
A12: 2020 | B12: 48 | C12: 53 | D12: 117 | E12: 120 | F12: 0 | G12: 0 | H12: 0 | I12: 0 | J12: =IF(B12=0,0,F12/B12) -> 0 | K12: =IF(C12=0,0,G12/C12) -> 0 | L12: =IF(D12=0,0,H12/D12) -> 0 | M12: =IF(E12=0,0,I12/E12) -> 0
A13: 2021 | B13: 43 | C13: 51 | D13: 186 | E13: 191 | F13: 0 | G13: 0 | H13: 0 | I13: 0 | J13: =IF(B13=0,0,F13/B13) -> 0 | K13: =IF(C13=0,0,G13/C13) -> 0 | L13: =IF(D13=0,0,H13/D13) -> 0 | M13: =IF(E13=0,0,I13/E13) -> 0
A14: 2022 | B14: 24 | C14: 28 | D14: 181 | E14: 187 | F14: 2 | G14: 2 | H14: 0 | I14: 0 | J14: =IF(B14=0,0,F14/B14) -> 0.083333333 | K14: =IF(C14=0,0,G14/C14) -> 0.071428571 | L14: =IF(D14=0,0,H14/D14) -> 0 | M14: =IF(E14=0,0,I14/E14) -> 0
A15: 2013-2022 | B15: =SUM(B5:B14) -> 528 | C15: =SUM(C5:C14) -> 604 | D15: =SUM(D5:D14) -> 2614 | E15: =SUM(E5:E14) -> 2663 | F15: =SUM(F5:F14) -> 10 | G15: =SUM(G5:G14) -> 13 | H15: =SUM(H5:H14) -> 3 | I15: =SUM(I5:I14) -> 3 | J15: =IF(B15=0,0,F15/B15) -> 0.018939394 | K15: =IF(C15=0,0,G15/C15) -> 0.021523179 | L15: =IF(D15=0,0,H15/D15) -> 0.0011476664 | M15: =IF(E15=0,0,I15/E15) -> 0.001126549

Sheet All Accidents 2016-22
A1: All accidents (all causes) by year and place - Coal mines
A2: Source: row 'ALL INDIA : ALL COAL' of the by-place-and-cause statement of each year. Total rows are formulas and equal the printed totals.
A4: Year | B4: Place | C4: Fatal accidents | D4: Persons killed | E4: Seriously injured in fatal accidents | F4: Serious accidents | G4: Seriously injured in serious accidents | H4: Total persons seriously injured
A5: 2016 | B5: Below Ground | C5: 26 | D5: 29 | E5: 3 | F5: 178 | G5: 178 | H5: =E5+G5 -> 181
A6: 2016 | B6: Opencast | C6: 30 | D6: 52 | E6: 2 | F6: 47 | G6: 47 | H6: =E6+G6 -> 49
A7: 2016 | B7: Above Ground | C7: 11 | D7: 13 | E7: 2 | F7: 44 | G7: 47 | H7: =E7+G7 -> 49
A8: 2016 | B8: Total | C8: =SUM(C5:C7) -> 67 | D8: =SUM(D5:D7) -> 94 | E8: =SUM(E5:E7) -> 7 | F8: =SUM(F5:F7) -> 269 | G8: =SUM(G5:G7) -> 272 | H8: =E8+G8 -> 279
A9: 2017 | B9: Below Ground | C9: 18 | D9: 21 | E9: 0 | F9: 190 | G9: 195 | H9: =E9+G9 -> 195
A10: 2017 | B10: Opencast | C10: 29 | D10: 29 | E10: 0 | F10: 32 | G10: 32 | H10: =E10+G10 -> 32
A11: 2017 | B11: Above Ground | C11: 9 | D11: 11 | E11: 0 | F11: 44 | G11: 45 | H11: =E11+G11 -> 45
A12: 2017 | B12: Total | C12: =SUM(C9:C11) -> 56 | D12: =SUM(D9:D11) -> 61 | E12: =SUM(E9:E11) -> 0 | F12: =SUM(F9:F11) -> 266 | G12: =SUM(G9:G11) -> 272 | H12: =E12+G12 -> 272
A13: 2018 | B13: Below Ground | C13: 12 | D13: 19 | E13: 1 | F13: 174 | G13: 177 | H13: =E13+G13 -> 178
A14: 2018 | B14: Opencast | C14: 29 | D14: 32 | E14: 3 | F14: 43 | G14: 43 | H14: =E14+G14 -> 46
A15: 2018 | B15: Above Ground | C15: 8 | D15: 11 | E15: 7 | F15: 48 | G15: 48 | H15: =E15+G15 -> 55
A16: 2018 | B16: Total | C16: =SUM(C13:C15) -> 49 | D16: =SUM(D13:D15) -> 62 | E16: =SUM(E13:E15) -> 11 | F16: =SUM(F13:F15) -> 265 | G16: =SUM(G13:G15) -> 268 | H16: =E16+G16 -> 279
A17: 2019 | B17: Below Ground | C17: 19 | D17: 21 | E17: 1 | F17: 127 | G17: 128 | H17: =E17+G17 -> 129
A18: 2019 | B18: Opencast | C18: 22 | D18: 25 | E18: 4 | F18: 30 | G18: 30 | H18: =E18+G18 -> 34
A19: 2019 | B19: Above Ground | C19: 10 | D19: 10 | E19: 1 | F19: 36 | G19: 40 | H19: =E19+G19 -> 41
A20: 2019 | B20: Total | C20: =SUM(C17:C19) -> 51 | D20: =SUM(D17:D19) -> 56 | E20: =SUM(E17:E19) -> 6 | F20: =SUM(F17:F19) -> 193 | G20: =SUM(G17:G19) -> 198 | H20: =E20+G20 -> 204
A21: 2020 | B21: Below Ground | C21: 15 | D21: 16 | E21: 6 | F21: 68 | G21: 69 | H21: =E21+G21 -> 75
A22: 2020 | B22: Opencast | C22: 24 | D22: 28 | E22: 12 | F22: 21 | G22: 22 | H22: =E22+G22 -> 34
A23: 2020 | B23: Above Ground | C23: 9 | D23: 9 | E23: 0 | F23: 28 | G23: 29 | H23: =E23+G23 -> 29
A24: 2020 | B24: Total | C24: =SUM(C21:C23) -> 48 | D24: =SUM(D21:D23) -> 53 | E24: =SUM(E21:E23) -> 18 | F24: =SUM(F21:F23) -> 117 | G24: =SUM(G21:G23) -> 120 | H24: =E24+G24 -> 138
A25: 2021 | B25: Below Ground | C25: 16 | D25: 21 | E25: 1 | F25: 108 | G25: 110 | H25: =E25+G25 -> 111
A26: 2021 | B26: Opencast | C26: 21 | D26: 23 | E26: 1 | F26: 32 | G26: 33 | H26: =E26+G26 -> 34
A27: 2021 | B27: Above Ground | C27: 6 | D27: 7 | E27: 0 | F27: 46 | G27: 48 | H27: =E27+G27 -> 48
A28: 2021 | B28: Total | C28: =SUM(C25:C27) -> 43 | D28: =SUM(D25:D27) -> 51 | E28: =SUM(E25:E27) -> 2 | F28: =SUM(F25:F27) -> 186 | G28: =SUM(G25:G27) -> 191 | H28: =E28+G28 -> 193
A29: 2022 | B29: Below Ground | C29: 9 | D29: 12 | E29: 2 | F29: 94 | G29: 98 | H29: =E29+G29 -> 100
A30: 2022 | B30: Opencast | C30: 11 | D30: 12 | E30: 1 | F30: 44 | G30: 46 | H30: =E30+G30 -> 47
A31: 2022 | B31: Above Ground | C31: 4 | D31: 4 | E31: 0 | F31: 43 | G31: 43 | H31: =E31+G31 -> 43
A32: 2022 | B32: Total | C32: =SUM(C29:C31) -> 24 | D32: =SUM(D29:D31) -> 28 | E32: =SUM(E29:E31) -> 3 | F32: =SUM(F29:F31) -> 181 | G32: =SUM(G29:G31) -> 187 | H32: =E32+G32 -> 190
A34: All years 2016-2022
A35: 2016-2022 | B35: Below Ground | C35: =SUMIFS(C$5:C$32,$B$5:$B$32,$B35) -> 115 | D35: =SUMIFS(D$5:D$32,$B$5:$B$32,$B35) -> 139 | E35: =SUMIFS(E$5:E$32,$B$5:$B$32,$B35) -> 14 | F35: =SUMIFS(F$5:F$32,$B$5:$B$32,$B35) -> 939 | G35: =SUMIFS(G$5:G$32,$B$5:$B$32,$B35) -> 955 | H35: =E35+G35 -> 969
A36: 2016-2022 | B36: Opencast | C36: =SUMIFS(C$5:C$32,$B$5:$B$32,$B36) -> 166 | D36: =SUMIFS(D$5:D$32,$B$5:$B$32,$B36) -> 201 | E36: =SUMIFS(E$5:E$32,$B$5:$B$32,$B36) -> 23 | F36: =SUMIFS(F$5:F$32,$B$5:$B$32,$B36) -> 249 | G36: =SUMIFS(G$5:G$32,$B$5:$B$32,$B36) -> 253 | H36: =E36+G36 -> 276
A37: 2016-2022 | B37: Above Ground | C37: =SUMIFS(C$5:C$32,$B$5:$B$32,$B37) -> 57 | D37: =SUMIFS(D$5:D$32,$B$5:$B$32,$B37) -> 65 | E37: =SUMIFS(E$5:E$32,$B$5:$B$32,$B37) -> 10 | F37: =SUMIFS(F$5:F$32,$B$5:$B$32,$B37) -> 289 | G37: =SUMIFS(G$5:G$32,$B$5:$B$32,$B37) -> 300 | H37: =E37+G37 -> 310
A38: 2016-2022 | B38: Total | C38: =SUMIFS(C$5:C$32,$B$5:$B$32,$B38) -> 338 | D38: =SUMIFS(D$5:D$32,$B$5:$B$32,$B38) -> 405 | E38: =SUMIFS(E$5:E$32,$B$5:$B$32,$B38) -> 47 | F38: =SUMIFS(F$5:F$32,$B$5:$B$32,$B38) -> 1477 | G38: =SUMIFS(G$5:G$32,$B$5:$B$32,$B38) -> 1508 | H38: =E38+G38 -> 1555

Sheet Notes
A1: Fire accidents - Coal mines, 2016-2022
A2: Source: DGMS 'SANKET' coal mine accident report (sanket-_coal.pdf); data years 2016-2022 (decade tables cover 2013-2022).
A4: Sheets
A5: Fire Accidents: 16 fatal accidents involving fire, burns or explosion, one row each, with the report's narrative and 'Had...' preventive analysis.
A6: Fire Stats 2016-22: the report's own category 'Dust, Gas & Other Combustible Material' by year and place (as printed).
A7: Fire by Place 2016-22, Fire by Company, Fire by Cause Group: counts from the Fire Accidents sheet, by formula.
A8: Fire Occurrences 2013-22: fire-related dangerous occurrences by year (Table 2.6), with fire share of all occurrences (formulas).
A9: Fire vs All 2013-22: the report's dust/gas/combustible category next to all-cause totals, with percentage shares (formulas).
A10: All Accidents 2016-22: all-cause fatal / serious accident totals by year and place.
A12: How fire is defined here
A13: DGMS has no separate fire category. The fire register is my selection of every fatal-accident narrative, 2016-22, that involves fire, burns from hot material, or an explosion of gas or flammable material. Cases sit under several report codes (see 'Cause category in report (code)').
A14: Cause group (column V) and place (column X) are my classification from the narrative. 'Fire or heating known beforehand' is 'Yes' only where the narrative says the area, strata, dump or bench was on fire.
... A29: Reconciliation checks (formulas)
